Workbook

Sheet Raw_Financials
B1: 2015 | C1: 2016 | D1: 2017 | E1: 2018 | F1: 2019 | G1: 2020 | H1: 2021 | I1: 2022 | J1: 2023 | K1: 2024
A2: Periods | B2: 12 | C2: 12 | D2: 12 | E2: 12 | F2: 12 | G2: 12 | H2: 12 | I2: 12 | J2: 12 | K2: 12
A3: Total Non-Current Assets | B3: =B22+B32+SUM(B33:B38)+SUM(B40:B46)-B39 -> 948303.32 | C3: =C22+C32+SUM(C33:C38)+SUM(C40:C46)-C39 -> 1132571.1 | D3: =D22+D32+SUM(D33:D38)+SUM(D40:D46)-D39 -> 1321849.3 | E3: =E22+E32+SUM(E33:E38)+SUM(E40:E46)-E39 -> 1666215.1 | F3: =F22+F32+SUM(F33:F38)+SUM(F40:F46)-F39 -> 2243152.9 | G3: =G22+G32+SUM(G33:G38)+SUM(G40:G46)-G39 -> 2519903.1 | H3: =H22+H32+SUM(H33:H38)+SUM(H40:H46)-H39 -> 3184128 | I3: =I22+I32+SUM(I33:I38)+SUM(I40:I46)-I39 -> 10090610 | ... K3: =K22+K32+SUM(K33:K38)+SUM(K40:K46)-K39 -> 24234704
A4: Total Current Assets | B4: =B56+B71+SUM(B57:B68)+SUM(B72:B75) -> 165868.98 | C4: =C56+C71+SUM(C57:C68)+SUM(C72:C75) -> 174481.95 | D4: =D56+D71+SUM(D57:D68)+SUM(D72:D75) -> 188553.52 | E4: =E56+E71+SUM(E57:E68)+SUM(E72:E75) -> 226511.52 | F4: =F56+F71+SUM(F57:F68)+SUM(F72:F75) -> 237941.1 | G4: =G56+G71+SUM(G57:G68)+SUM(G72:G75) -> 438016.49 | H4: =H56+H71+SUM(H57:H68)+SUM(H72:H75) -> 443279.05 | I4: =I56+I71+SUM(I57:I68)+SUM(I72:I75) -> 2104055.3 | ... K4: =K56+K71+SUM(K57:K68)+SUM(K72:K75) -> 6510695
A5: Total Equity & Reserves | B5: =+B82+B93+B94 -> -18816.879 | C5: =+C82+C93+C94 -> -6374.964 | D5: =+D82+D93+D94 -> -11517.088 | E5: =+E82+E93+E94 -> -13802.036 | F5: =+F82+F93+F94 -> 41655.046 | G5: =+G82+G93+G94 -> 16267.905 | H5: =+H82+H93+H94 -> 12877.404 | I5: =+I82+I93+I94 -> 5810755.9 | ... K5: =+K82+K93+K94 -> 17097795
A6: Total Non-Current Liabilities | B6: =+B100+B108+B111+B122 -> 949085.87 | C6: =+C100+C108+C111+C122 -> 1047559.2 | D6: =+D100+D108+D111+D122 -> 1145402.9 | E6: =+E100+E108+E111+E122 -> 1379534.1 | F6: =+F100+F108+F111+F122 -> 1935837.4 | G6: =+G100+G108+G111+G122 -> 2250777.5 | H6: =+H100+H108+H111+H122 -> 2512094.9 | I6: =+I100+I108+I111+I122 -> 3259756.4 | ... K6: =+K100+K108+K111+K122 -> 11149770
A7: Total Current Liabilities | B7: =+B135+B138+B140+B158 -> 177777.95 | C7: =+C135+C138+C140+C158 -> 265868.83 | D7: =+D135+D138+D140+D158 -> 376517.02 | E7: =+E135+E138+E140+E158 -> 526994.59 | F7: =+F135+F138+F140+F158 -> 503601.55 | G7: =+G135+G138+G140+G158 -> 690874.17 | H7: =+H135+H138+H140+H158 -> 1102434.7 | I7: =+I135+I138+I140+I158 -> 3124153 | ... K7: =+K135+K138+K140+K158 -> 2497833.1
A8: Total Income & Expenses | B8: =+B222+SUM(B223:B225) -> 284286.33 | C8: =+C222+SUM(C223:C225) -> -72133.792 | D8: =+D222+SUM(D223:D225) -> -7653.73 | E8: =+E222+SUM(E223:E225) -> -2785.898 | F8: =+F222+SUM(F223:F225) -> 15228.112 | G8: =+G222+SUM(G223:G225) -> -150451.34 | H8: =+H222+SUM(H223:H225) -> -16279.273 | I8: =+I222+SUM(I223:I225) -> 167380.9 | ... K8: =+K222+SUM(K223:K225) -> 1111728.1
A9: Total Assets | B9: =+B3+B4 -> 1114172.3 | C9: =+C3+C4 -> 1307053 | D9: =+D3+D4 -> 1510402.8 | E9: =+E3+E4 -> 1892726.6 | F9: =+F3+F4 -> 2481094 | G9: =+G3+G4 -> 2957919.6 | H9: =+H3+H4 -> 3627407 | I9: =+I3+I4 -> 12194665 | ... K9: =+K3+K4 -> 30745399
A10: Total Liabs & Net Worth | B10: =+B5+B6+B7 -> 1108046.9 | C10: =+C5+C6+C7 -> 1307053 | D10: =+D5+D6+D7 -> 1510402.8 | E10: =+E5+E6+E7 -> 1892726.6 | F10: =+F5+F6+F7 -> 2481094 | G10: =+G5+G6+G7 -> 2957919.6 | H10: =+H5+H6+H7 -> 3627407 | I10: =+I5+I6+I7 -> 12194665 | ... K10: =+K5+K6+K7 -> 30745399
A11: Land | B11: 14032.667 | C11: 14032.667 | D11: 23403.323 | E11: 33060.353 | F11: 103852.85 | G11: 101279.09 | H11: 98968.693 | I11: 120278.06 | J11: 290929.45 | K11: 448557.67
A12: Buildings | B12: 833762.12 | C12: 1043360.1 | D12: 1260884.4 | E12: 1617813.9 | F12: 1804326.9 | G12: 2078253.5 | H12: 2557937 | I12: 7193567.1 | J12: 13525188 | K12: 16975662
A13: Leasehold Improvements | B13: 1403.519 | C13: 1427.037 | D13: 2041.371 | E13: 2721.856 | F13: 3448.04 | G13: 3453.29 | H13: 3511.326 | I13: 19925.234 | J13: 25704.472 | K13: 28709.24
A14: Plant & Equipment | B14: 20939.671 | C14: 25333.043 | D14: 29666.922 | E14: 34707.234 | F14: 36676.018 | G14: 41352.778 | H14: 49195.082 | I14: 215053.46 | J14: 368293.23 | K14: 432329.51
A15: Furniture & Fixtures | B15: 119819.36 | C15: 153420.68 | D15: 181671.88 | E15: 206840.7 | F15: 240029.24 | G15: 259654.77 | H15: 304228.85 | I15: 1555545.8 | J15: 2211598.6 | K15: 2915529
A16: Vehicles & Transport Equipment | B16: 78074.387 | C16: 78665.806 | D16: 111033.76 | E16: 140028.73 | F16: 158375.26 | G16: 194663.89 | H16: 208611.15 | I16: 905914.41 | J16: 1260059.8 | K16: 952913.3
A17: Other Fixed Assets | B17: 0 | C17: 0 | D17: 0 | E17: 0 | F17: 0 | G17: 0 | H17: 0 | I17: 14708.053 | J17: 35116.507 | K17: 156914.68
A18: Construction in Progress | B18: 14039.53 | C18: 2262.903 | D18: 1688.715 | E18: 766.351 | F18: 1314.864 | G18: 5537.918 | H18: 69886.989 | I18: 3029387 | J18: 3600896.8 | K18: 7964508.4
A19: Property Development Investments | B19: 0 | C19: 0 | D19: 0 | E19: 0 | F19: 0 | G19: 0 | H19: 0 | I19: 0 | J19: 0 | K19: 0
A20: Gross Fixed Assets | B20: =SUM(B11:B19) -> 1082071.3 | C20: =SUM(C11:C19) -> 1318502.2 | D20: =SUM(D11:D19) -> 1610390.4 | E20: =SUM(E11:E19) -> 2035939.1 | F20: =SUM(F11:F19) -> 2348023.1 | G20: =SUM(G11:G19) -> 2684195.2 | H20: =SUM(H11:H19) -> 3292339 | I20: =SUM(I11:I19) -> 13054379 | ... K20: =SUM(K11:K19) -> 29875124
A21: Accum Deprec & Impairment (-) | B21: 171723.6 | C21: 232985.01 | D21: 312488.9 | E21: 411010.59 | F21: 509449.8 | G21: 618698.62 | H21: 747092.1 | I21: 3843932.8 | J21: 5434710.7 | K21: 7103298
A22: Net Fixed Assets | B22: =+B20-B21 -> 910347.65 | C22: =+C20-C21 -> 1085517.2 | D22: =+D20-D21 -> 1297901.5 | E22: =+E20-E21 -> 1624928.5 | F22: =+F20-F21 -> 1838573.3 | G22: =+G20-G21 -> 2065496.6 | H22: =+H20-H21 -> 2545246.9 | I22: =+I20-I21 -> 9210446.3 | ... K22: =+K20-K21 -> 22771826
A23: Goodwill | B23: 5018.69 | C23: 5018.69 | D23: 5018.689 | E23: 5018.689 | F23: 5018.689 | G23: 5018.689 | H23: 45902.294 | I23: 5018.689 | J23: 5018.689 | K23: 5018.689
A24: Goodwill impairment(-) | B24: 0 | C24: 0 | D24: 0 | E24: 0 | F24: 0 | G24: 0 | H24: 0 | I24: 0 | J24: 0 | K24: 0
A25: Concessions, Licenses & Trdmrks | B25: 0 | C25: 0 | D25: 0 | E25: 0 | F25: 0 | G25: 0 | H25: 0 | I25: 0 | J25: 0 | K25: 0
A26: Patents | B26: 0 | C26: 0 | D26: 0 | E26: 0 | F26: 0 | G26: 0 | H26: 0 | I26: 0 | J26: 0 | K26: 0
A27: Start-Up Capitalized Expenses | B27: 0 | C27: 0 | D27: 0 | E27: 0 | F27: 0 | G27: 0 | H27: 0 | I27: 0 | J27: 0 | K27: 0
A28: R&D Capitalized Expenses | B28: 0 | C28: 0 | D28: 0 | E28: 0 | F28: 0 | G28: 0 | H28: 0 | I28: 0 | J28: 0 | K28: 0
A29: Leasings | B29: 0 | C29: 0 | D29: 0 | E29: 0 | F29: 0 | G29: 0 | H29: 0 | I29: 0 | J29: 0 | K29: 0
A30: Other Intangible Assets | B30: 1171.631 | C30: 13580.647 | D30: 14037.345 | E30: 39713.438 | F30: 40539.995 | G30: 41274.217 | H30: 46182.106 | I30: 531466.26 | J30: 758034.45 | K30: 1025764.9
A31: Accum Intgbl Assets Amort(-) | B31: 0 | C31: 8777.925 | D31: 11429.745 | E31: 18887.544 | F31: 26246.241 | G31: 32292.361 | H31: 39465.957 | I31: 370735.58 | J31: 586587.06 | K31: 793925.07
A32: Net Intangibles | B32: =+B23-B24+SUM(B25:B30)-B31 -> 6190.321 | C32: =+C23-C24+SUM(C25:C30)-C31 -> 9821.412 | D32: =+D23-D24+SUM(D25:D30)-D31 -> 7626.289 | E32: =+E23-E24+SUM(E25:E30)-E31 -> 25844.583 | F32: =+F23-F24+SUM(F25:F30)-F31 -> 19312.443 | G32: =+G23-G24+SUM(G25:G30)-G31 -> 14000.545 | H32: =+H23-H24+SUM(H25:H30)-H31 -> 52618.443 | I32: =+I23-I24+SUM(I25:I30)-I31 -> 165749.36 | ... K32: =+K23-K24+SUM(K25:K30)-K31 -> 236858.56
A33: Investments in Group Companies and LT Associates | B33: 744.224 | C33: 979.224 | D33: 9934.645 | E33: 11068.502 | F33: 17929.224 | G33: 15245.519 | H33: 41104.146 | I33: 75974.125 | J33: 310568.03 | K33: 557041.8
A34: Investments in Associates | B34: 499.623 | C34: 11206.319 | D34: 0 | E34: 0 | F34: 0 | G34: 0 | H34: 0 | I34: 0 | J34: 0 | K34: 0
A35: Invest in JVs & Partnerships | B35: 0 | C35: 0 | D35: 0 | E35: 0 | F35: 0 | G35: 0 | H35: 0 | I35: 0 | J35: 0 | K35: 0
A36: Due from Related Parties(LTP) | B36: 13057.348 | C36: 1874.545 | D36: 0 | E36: 0 | F36: 0 | G36: 0 | H36: 0 | I36: 0 | J36: 0 | K36: 0
A37: Due from S'holder(LTP) | B37: 3939.969 | C37: 14655.045 | D37: 0 | E37: 0 | F37: 0 | G37: 0 | H37: 0 | I37: 47724.664 | J37: 0 | K37: 0
A38: Secur & Other Fincl Assets(LTP) | B38: 0 | C38: 0 | D38: 0 | E38: 0 | F38: 0 | G38: 0 | H38: 0 | I38: 0 | J38: 0 | K38: 0
A39: Accum Deprec of Financial Assets(-) | B39: 0 | C39: 0 | D39: 0 | E39: 0 | F39: 0 | G39: 0 | H39: 0 | I39: 0 | J39: 0 | K39: 0
A40: Deriv & Hedg Assets(LTP) | B40: 0 | C40: 0 | D40: 0 | E40: 0 | F40: 0 | G40: 0 | H40: 0 | I40: 0 | J40: 0 | K40: 0
...

Sheet FXs
A1: Yıl | B1: USD_Avg | C1: USD_End
A2: 2015 | B2: =+AVERAGE(Macro_Monthly!B2:B13) -> 2.7186517 | C2: =+Macro_Monthly!B13 -> 2.9172348
A3: 2016 | B3: =+AVERAGE(Macro_Monthly!B14:B25) -> 3.0185425 | C3: =+Macro_Monthly!B25 -> 3.4889273
A4: 2017 | B4: =+AVERAGE(Macro_Monthly!B26:B37) -> 3.6449402 | C4: =+Macro_Monthly!B37 -> 3.8477048
A5: 2018 | B5: =+AVERAGE(Macro_Monthly!B38:B49) -> 4.8259734 | C5: =+Macro_Monthly!B49 -> 5.3061238
A6: 2019 | B6: =+AVERAGE(Macro_Monthly!B50:B61) -> 5.6694745 | C6: =+Macro_Monthly!B61 -> 5.8376273
A7: 2020 | B7: =+AVERAGE(Macro_Monthly!B62:B73) -> 7.0055108 | C7: =+Macro_Monthly!B73 -> 7.7210652
A8: 2021 | B8: =+AVERAGE(Macro_Monthly!B74:B85) -> 8.831731 | C8: =+Macro_Monthly!B85 -> 13.528496
A9: 2022 | B9: =+AVERAGE(Macro_Monthly!B86:B97) -> 16.53621 | C9: =+Macro_Monthly!B97 -> 18.636968
A10: 2023 | B10: =+AVERAGE(Macro_Monthly!B98:B109) -> 23.693283 | C10: =+Macro_Monthly!B109 -> 29.022562
A11: 2024 | B11: =+AVERAGE(Macro_Monthly!B110:B121) -> 32.780165 | C11: =+Macro_Monthly!B121 -> 34.903823

Sheet converted2usd+IQR
B1: 2015 | C1: 2016 | D1: 2017 | E1: 2018 | F1: 2019 | G1: 2020 | H1: 2021 | I1: 2022 | J1: 2023 | K1: 2024 | L1: Q1 | M1: Q3 | N1: IQR | O1: Alt Sınır | P1: Üst Sınır
A2: Periods | B2: 12 | C2: 12 | D2: 12 | E2: 12 | F2: 12 | G2: 12 | H2: 12 | I2: 12 | J2: 12 | K2: 12
A3: Total Non-Current Assets | B3: =+Raw_Financials!B3/FXs!$C$2 -> 325069.25 | C3: =+Raw_Financials!C3/FXs!$C$3 -> 324618.71 | D3: =+Raw_Financials!D3/FXs!$C$4 -> 343542.28 | E3: =+Raw_Financials!E3/FXs!$C$5 -> 314017.38 | F3: =+Raw_Financials!F3/FXs!$C$6 -> 384257.64 | G3: =+Raw_Financials!G3/FXs!$C$7 -> 326367.29 | H3: =+Raw_Financials!H3/FXs!$C$8 -> 235364.53 | I3: =+Raw_Financials!I3/FXs!$C$9 -> 541429.79 | J3: =+Raw_Financials!J3/FXs!$C$10 -> 590914.77 | K3: =+Raw_Financials!K3/FXs!$C$11 -> 694328.07 | L3: =QUARTILE(B3:K3, 1) -> 324731.35 | M3: =QUARTILE(B3:K3, 3) -> 502136.76 | N3: =M3 - L3 -> 177405.41 | O3: =L3 - (3 * N3) -> -207484.88 | P3: =M3 + (3 * N3) -> 1034353
A4: Total Current Assets | B4: =+Raw_Financials!B4/FXs!$C$2 -> 56858.288 | C4: =+Raw_Financials!C4/FXs!$C$3 -> 50010.201 | D4: =+Raw_Financials!D4/FXs!$C$4 -> 49004.156 | E4: =+Raw_Financials!E4/FXs!$C$5 -> 42688.698 | F4: =+Raw_Financials!F4/FXs!$C$6 -> 40759.899 | G4: =+Raw_Financials!G4/FXs!$C$7 -> 56730.06 | H4: =+Raw_Financials!H4/FXs!$C$8 -> 32766.323 | I4: =+Raw_Financials!I4/FXs!$C$9 -> 112896.87 | J4: =+Raw_Financials!J4/FXs!$C$10 -> 106971.13 | K4: =+Raw_Financials!K4/FXs!$C$11 -> 186532.43 | L4: =QUARTILE(B4:K4, 1) -> 44267.562 | M4: =QUARTILE(B4:K4, 3) -> 94442.916 | N4: =M4 - L4 -> 50175.354 | O4: =L4 - (3 * N4) -> -106258.5 | P4: =M4 + (3 * N4) -> 244968.98
A5: Total Equity & Reserves | B5: =+Raw_Financials!B5/FXs!$C$2 -> -6450.245 | C5: =+Raw_Financials!C5/FXs!$C$3 -> -1827.1989 | D5: =+Raw_Financials!D5/FXs!$C$4 -> -2993.2359 | E5: =+Raw_Financials!E5/FXs!$C$5 -> -2601.1523 | F5: =+Raw_Financials!F5/FXs!$C$6 -> 7135.6125 | G5: =+Raw_Financials!G5/FXs!$C$7 -> 2106.9509 | H5: =+Raw_Financials!H5/FXs!$C$8 -> 951.87258 | I5: =+Raw_Financials!I5/FXs!$C$9 -> 311786.54 | J5: =+Raw_Financials!J5/FXs!$C$10 -> 372232.02 | K5: =+Raw_Financials!K5/FXs!$C$11 -> 489854.52 | L5: =QUARTILE(B5:K5, 1) -> -2407.6639 | M5: =QUARTILE(B5:K5, 3) -> 235623.81 | N5: =M5 - L5 -> 238031.47 | O5: =L5 - (3 * N5) -> -716502.09 | P5: =M5 + (3 * N5) -> 949718.23
A6: Total Non-Current Liabilities | B6: =+Raw_Financials!B6/FXs!$C$2 -> 325337.5 | C6: =+Raw_Financials!C6/FXs!$C$3 -> 300252.51 | D6: =+Raw_Financials!D6/FXs!$C$4 -> 297684.71 | E6: =+Raw_Financials!E6/FXs!$C$5 -> 259989.04 | F6: =+Raw_Financials!F6/FXs!$C$6 -> 331613.73 | G6: =+Raw_Financials!G6/FXs!$C$7 -> 291511.27 | H6: =+Raw_Financials!H6/FXs!$C$8 -> 185689.16 | I6: =+Raw_Financials!I6/FXs!$C$9 -> 174908.08 | J6: =+Raw_Financials!J6/FXs!$C$10 -> 183385.17 | K6: =+Raw_Financials!K6/FXs!$C$11 -> 319442.67 | L6: =QUARTILE(B6:K6, 1) -> 204264.13 | M6: =QUARTILE(B6:K6, 3) -> 314645.13 | N6: =M6 - L6 -> 110381 | O6: =L6 - (3 * N6) -> -126878.88 | P6: =M6 + (3 * N6) -> 645788.14
A7: Total Current Liabilities | B7: =+Raw_Financials!B7/FXs!$C$2 -> 60940.571 | C7: =+Raw_Financials!C7/FXs!$C$3 -> 76203.605 | D7: =+Raw_Financials!D7/FXs!$C$4 -> 97854.966 | E7: =+Raw_Financials!E7/FXs!$C$5 -> 99318.186 | F7: =+Raw_Financials!F7/FXs!$C$6 -> 86268.191 | G7: =+Raw_Financials!G7/FXs!$C$7 -> 89479.126 | H7: =+Raw_Financials!H7/FXs!$C$8 -> 81489.822 | I7: =+Raw_Financials!I7/FXs!$C$9 -> 167632.04 | J7: =+Raw_Financials!J7/FXs!$C$10 -> 142268.71 | K7: =+Raw_Financials!K7/FXs!$C$11 -> 71563.311 | L7: =QUARTILE(B7:K7, 1) -> 77525.159 | M7: =QUARTILE(B7:K7, 3) -> 98952.381 | N7: =M7 - L7 -> 21427.222 | O7: =L7 - (3 * N7) -> 13243.494 | P7: =M7 + (3 * N7) -> 163234.05
A8: Total Income & Expenses | B8: =+Raw_Financials!B8/FXs!$C$2 -> 97450.616 | C8: =+Raw_Financials!C8/FXs!$C$3 -> -20675.063 | D8: =+Raw_Financials!D8/FXs!$C$4 -> -1989.1677 | E8: =+Raw_Financials!E8/FXs!$C$5 -> -525.03449 | F8: =+Raw_Financials!F8/FXs!$C$6 -> 2608.6133 | G8: =+Raw_Financials!G8/FXs!$C$7 -> -19485.826 | H8: =+Raw_Financials!H8/FXs!$C$8 -> -1203.3321 | I8: =+Raw_Financials!I8/FXs!$C$9 -> 8981.1225 | J8: =+Raw_Financials!J8/FXs!$C$10 -> -2255.0462 | K8: =+Raw_Financials!K8/FXs!$C$11 -> 31851.185 | L8: =QUARTILE(B8:K8, 1) -> -2188.5766 | M8: =QUARTILE(B8:K8, 3) -> 7387.9952 | N8: =M8 - L8 -> 9576.5718 | O8: =L8 - (3 * N8) -> -30918.292 | P8: =M8 + (3 * N8) -> 36117.711
A9: Total Assets | B9: =+Raw_Financials!B9/FXs!$C$2 -> 381927.54 | C9: =+Raw_Financials!C9/FXs!$C$3 -> 374628.91 | D9: =+Raw_Financials!D9/FXs!$C$4 -> 392546.43 | E9: =+Raw_Financials!E9/FXs!$C$5 -> 356706.08 | F9: =+Raw_Financials!F9/FXs!$C$6 -> 425017.54 | G9: =+Raw_Financials!G9/FXs!$C$7 -> 383097.35 | H9: =+Raw_Financials!H9/FXs!$C$8 -> 268130.85 | I9: =+Raw_Financials!I9/FXs!$C$9 -> 654326.66 | J9: =+Raw_Financials!J9/FXs!$C$10 -> 697885.9 | K9: =+Raw_Financials!K9/FXs!$C$11 -> 880860.51 | L9: =QUARTILE(B9:K9, 1) -> 376453.57 | M9: =QUARTILE(B9:K9, 3) -> 596999.38 | N9: =M9 - L9 -> 220545.81 | O9: =L9 - (3 * N9) -> -285183.87 | P9: =M9 + (3 * N9) -> 1258636.8
A10: Total Liabs & Net Worth | B10: =+Raw_Financials!B10/FXs!$C$2 -> 379827.82 | C10: =+Raw_Financials!C10/FXs!$C$3 -> 374628.91 | D10: =+Raw_Financials!D10/FXs!$C$4 -> 392546.44 | E10: =+Raw_Financials!E10/FXs!$C$5 -> 356706.08 | F10: =+Raw_Financials!F10/FXs!$C$6 -> 425017.54 | G10: =+Raw_Financials!G10/FXs!$C$7 -> 383097.35 | H10: =+Raw_Financials!H10/FXs!$C$8 -> 268130.85 | I10: =+Raw_Financials!I10/FXs!$C$9 -> 654326.66 | J10: =+Raw_Financials!J10/FXs!$C$10 -> 697885.9 | K10: =+Raw_Financials!K10/FXs!$C$11 -> 880860.51 | L10: =QUARTILE(B10:K10, 1) -> 375928.64 | M10: =QUARTILE(B10:K10, 3) -> 596999.38 | N10: =M10 - L10 -> 221070.74 | O10: =L10 - (3 * N10) -> -287283.59 | P10: =M10 + (3 * N10) -> 1260211.6
A11: Land | B11: =+Raw_Financials!B11/FXs!$C$2 -> 4810.2632 | C11: =+Raw_Financials!C11/FXs!$C$3 -> 4022.0578 | D11: =+Raw_Financials!D11/FXs!$C$4 -> 6082.4113 | E11: =+Raw_Financials!E11/FXs!$C$5 -> 6230.6034 | F11: =+Raw_Financials!F11/FXs!$C$6 -> 17790.25 | G11: =+Raw_Financials!G11/FXs!$C$7 -> 13117.244 | H11: =+Raw_Financials!H11/FXs!$C$8 -> 7315.5727 | I11: =+Raw_Financials!I11/FXs!$C$9 -> 6453.7354 | J11: =+Raw_Financials!J11/FXs!$C$10 -> 10024.251 | K11: =+Raw_Financials!K11/FXs!$C$11 -> 12851.248 | L11: =QUARTILE(B11:K11, 1) -> 6119.4593 | M11: =QUARTILE(B11:K11, 3) -> 12144.499 | N11: =M11 - L11 -> 6025.0392 | O11: =L11 - (3 * N11) -> -11955.658 | P11: =M11 + (3 * N11) -> 30219.616
A12: Buildings | B12: =+Raw_Financials!B12/FXs!$C$2 -> 285805.63 | C12: =+Raw_Financials!C12/FXs!$C$3 -> 299048.97 | D12: =+Raw_Financials!D12/FXs!$C$4 -> 327697.8 | E12: =+Raw_Financials!E12/FXs!$C$5 -> 304895.62 | F12: =+Raw_Financials!F12/FXs!$C$6 -> 309085.66 | G12: =+Raw_Financials!G12/FXs!$C$7 -> 269166.68 | H12: =+Raw_Financials!H12/FXs!$C$8 -> 189077.71 | I12: =+Raw_Financials!I12/FXs!$C$9 -> 385983.76 | J12: =+Raw_Financials!J12/FXs!$C$10 -> 466023.22 | K12: =+Raw_Financials!K12/FXs!$C$11 -> 486355.39 | L12: =QUARTILE(B12:K12, 1) -> 289116.46 | M12: =QUARTILE(B12:K12, 3) -> 371412.27 | N12: =M12 - L12 -> 82295.808 | O12: =L12 - (3 * N12) -> 42229.039 | P12: =M12 + (3 * N12) -> 618299.7
A13: Leasehold Improvements | B13: =+Raw_Financials!B13/FXs!$C$2 -> 481.1128 | C13: =+Raw_Financials!C13/FXs!$C$3 -> 409.01884 | D13: =+Raw_Financials!D13/FXs!$C$4 -> 530.54253 | E13: =+Raw_Financials!E13/FXs!$C$5 -> 512.96504 | F13: =+Raw_Financials!F13/FXs!$C$6 -> 590.65779 | G13: =+Raw_Financials!G13/FXs!$C$7 -> 447.25564 | H13: =+Raw_Financials!H13/FXs!$C$8 -> 259.55037 | I13: =+Raw_Financials!I13/FXs!$C$9 -> 1069.1242 | J13: =+Raw_Financials!J13/FXs!$C$10 -> 885.67205 | K13: =+Raw_Financials!K13/FXs!$C$11 -> 822.52423 | L13: =QUARTILE(B13:K13, 1) -> 455.71993 | M13: =QUARTILE(B13:K13, 3) -> 764.55762 | N13: =M13 - L13 -> 308.83769 | O13: =L13 - (3 * N13) -> -470.79313 | P13: =M13 + (3 * N13) -> 1691.0707
A14: Plant & Equipment | B14: =+Raw_Financials!B14/FXs!$C$2 -> 7177.9176 | C14: =+Raw_Financials!C14/FXs!$C$3 -> 7260.9834 | D14: =+Raw_Financials!D14/FXs!$C$4 -> 7710.2906 | E14: =+Raw_Financials!E14/FXs!$C$5 -> 6540.977 | F14: =+Raw_Financials!F14/FXs!$C$6 -> 6282.6927 | G14: =+Raw_Financials!G14/FXs!$C$7 -> 5355.8385 | H14: =+Raw_Financials!H14/FXs!$C$8 -> 3636.4045 | I14: =+Raw_Financials!I14/FXs!$C$9 -> 11539.079 | J14: =+Raw_Financials!J14/FXs!$C$10 -> 12689.894 | K14: =+Raw_Financials!K14/FXs!$C$11 -> 12386.308 | L14: =QUARTILE(B14:K14, 1) -> 6347.2638 | M14: =QUARTILE(B14:K14, 3) -> 10581.882 | N14: =M14 - L14 -> 4234.6185 | O14: =L14 - (3 * N14) -> -6356.5918 | P14: =M14 + (3 * N14) -> 23285.738
... A225: Minority Interests | B225: =+Raw_Financials!B225/FXs!$C$2 -> 0 | C225: =+Raw_Financials!C225/FXs!$C$3 -> 0 | D225: =+Raw_Financials!D225/FXs!$C$4 -> 0 | E225: =+Raw_Financials!E225/FXs!$C$5 -> 0 | F225: =+Raw_Financials!F225/FXs!$C$6 -> 0 | G225: =+Raw_Financials!G225/FXs!$C$7 -> 0 | H225: =+Raw_Financials!H225/FXs!$C$8 -> 0 | I225: =+Raw_Financials!I225/FXs!$C$9 -> 0 | J225: =+Raw_Financials!J225/FXs!$C$10 -> 0 | K225: =+Raw_Financials!K225/FXs!$C$11 -> 0 | L225: =QUARTILE(B225:K225, 1) -> 0 | M225: =QUARTILE(B225:K225, 3) -> 0 | N225: =M225 - L225 -> 0 | O225: =L225 - (3 * N225) -> 0 | P225: =M225 + (3 * N225) -> 0

Sheet IQR_results_usd
B1: 2015 | C1: 2016 | D1: 2017 | E1: 2018 | F1: 2019 | G1: 2020 | H1: 2021 | I1: 2022 | J1: 2023 | K1: 2024
A2: Periods | B2: 12 | C2: 12 | D2: 12 | E2: 12 | F2: 12 | G2: 12 | H2: 12 | I2: 12 | J2: 12 | K2: 12
A3: Total Non-Current Assets | B3: =MEDIAN('converted2usd+IQR'!B3, 'converted2usd+IQR'!$O3, 'converted2usd+IQR'!$P3) -> 325069.25 | C3: =MEDIAN('converted2usd+IQR'!C3, 'converted2usd+IQR'!$O3, 'converted2usd+IQR'!$P3) -> 324618.71 | D3: =MEDIAN('converted2usd+IQR'!D3, 'converted2usd+IQR'!$O3, 'converted2usd+IQR'!$P3) -> 343542.28 | E3: =MEDIAN('converted2usd+IQR'!E3, 'converted2usd+IQR'!$O3, 'converted2usd+IQR'!$P3) -> 314017.38 | F3: =MEDIAN('converted2usd+IQR'!F3, 'converted2usd+IQR'!$O3, 'converted2usd+IQR'!$P3) -> 384257.64 | G3: =MEDIAN('converted2usd+IQR'!G3, 'converted2usd+IQR'!$O3, 'converted2usd+IQR'!$P3) -> 326367.29 | H3: =MEDIAN('converted2usd+IQR'!H3, 'converted2usd+IQR'!$O3, 'converted2usd+IQR'!$P3) -> 235364.53 | I3: =MEDIAN('converted2usd+IQR'!I3, 'converted2usd+IQR'!$O3, 'converted2usd+IQR'!$P3) -> 541429.79 | ... K3: =MEDIAN('converted2usd+IQR'!K3, 'converted2usd+IQR'!$O3, 'converted2usd+IQR'!$P3) -> 694328.07
A4: Total Current Assets | B4: =MEDIAN('converted2usd+IQR'!B4, 'converted2usd+IQR'!$O4, 'converted2usd+IQR'!$P4) -> 56858.288 | C4: =MEDIAN('converted2usd+IQR'!C4, 'converted2usd+IQR'!$O4, 'converted2usd+IQR'!$P4) -> 50010.201 | D4: =MEDIAN('converted2usd+IQR'!D4, 'converted2usd+IQR'!$O4, 'converted2usd+IQR'!$P4) -> 49004.156 | E4: =MEDIAN('converted2usd+IQR'!E4, 'converted2usd+IQR'!$O4, 'converted2usd+IQR'!$P4) -> 42688.698 | F4: =MEDIAN('converted2usd+IQR'!F4, 'converted2usd+IQR'!$O4, 'converted2usd+IQR'!$P4) -> 40759.899 | G4: =MEDIAN('converted2usd+IQR'!G4, 'converted2usd+IQR'!$O4, 'converted2usd+IQR'!$P4) -> 56730.06 | H4: =MEDIAN('converted2usd+IQR'!H4, 'converted2usd+IQR'!$O4, 'converted2usd+IQR'!$P4) -> 32766.323 | I4: =MEDIAN('converted2usd+IQR'!I4, 'converted2usd+IQR'!$O4, 'converted2usd+IQR'!$P4) -> 112896.87 | ... K4: =MEDIAN('converted2usd+IQR'!K4, 'converted2usd+IQR'!$O4, 'converted2usd+IQR'!$P4) -> 186532.43
A5: Total Equity & Reserves | B5: =MEDIAN('converted2usd+IQR'!B5, 'converted2usd+IQR'!$O5, 'converted2usd+IQR'!$P5) -> -6450.245 | C5: =MEDIAN('converted2usd+IQR'!C5, 'converted2usd+IQR'!$O5, 'converted2usd+IQR'!$P5) -> -1827.1989 | D5: =MEDIAN('converted2usd+IQR'!D5, 'converted2usd+IQR'!$O5, 'converted2usd+IQR'!$P5) -> -2993.2359 | E5: =MEDIAN('converted2usd+IQR'!E5, 'converted2usd+IQR'!$O5, 'converted2usd+IQR'!$P5) -> -2601.1523 | F5: =MEDIAN('converted2usd+IQR'!F5, 'converted2usd+IQR'!$O5, 'converted2usd+IQR'!$P5) -> 7135.6125 | G5: =MEDIAN('converted2usd+IQR'!G5, 'converted2usd+IQR'!$O5, 'converted2usd+IQR'!$P5) -> 2106.9509 | H5: =MEDIAN('converted2usd+IQR'!H5, 'converted2usd+IQR'!$O5, 'converted2usd+IQR'!$P5) -> 951.87258 | I5: =MEDIAN('converted2usd+IQR'!I5, 'converted2usd+IQR'!$O5, 'converted2usd+IQR'!$P5) -> 311786.54 | ... K5: =MEDIAN('converted2usd+IQR'!K5, 'converted2usd+IQR'!$O5, 'converted2usd+IQR'!$P5) -> 489854.52
A6: Total Non-Current Liabilities | B6: =MEDIAN('converted2usd+IQR'!B6, 'converted2usd+IQR'!$O6, 'converted2usd+IQR'!$P6) -> 325337.5 | C6: =MEDIAN('converted2usd+IQR'!C6, 'converted2usd+IQR'!$O6, 'converted2usd+IQR'!$P6) -> 300252.51 | D6: =MEDIAN('converted2usd+IQR'!D6, 'converted2usd+IQR'!$O6, 'converted2usd+IQR'!$P6) -> 297684.71 | E6: =MEDIAN('converted2usd+IQR'!E6, 'converted2usd+IQR'!$O6, 'converted2usd+IQR'!$P6) -> 259989.04 | F6: =MEDIAN('converted2usd+IQR'!F6, 'converted2usd+IQR'!$O6, 'converted2usd+IQR'!$P6) -> 331613.73 | G6: =MEDIAN('converted2usd+IQR'!G6, 'converted2usd+IQR'!$O6, 'converted2usd+IQR'!$P6) -> 291511.27 | H6: =MEDIAN('converted2usd+IQR'!H6, 'converted2usd+IQR'!$O6, 'converted2usd+IQR'!$P6) -> 185689.16 | I6: =MEDIAN('converted2usd+IQR'!I6, 'converted2usd+IQR'!$O6, 'converted2usd+IQR'!$P6) -> 174908.08 | ... K6: =MEDIAN('converted2usd+IQR'!K6, 'converted2usd+IQR'!$O6, 'converted2usd+IQR'!$P6) -> 319442.67
A7: Total Current Liabilities | B7: =MEDIAN('converted2usd+IQR'!B7, 'converted2usd+IQR'!$O7, 'converted2usd+IQR'!$P7) -> 60940.571 | C7: =MEDIAN('converted2usd+IQR'!C7, 'converted2usd+IQR'!$O7, 'converted2usd+IQR'!$P7) -> 76203.605 | D7: =MEDIAN('converted2usd+IQR'!D7, 'converted2usd+IQR'!$O7, 'converted2usd+IQR'!$P7) -> 97854.966 | E7: =MEDIAN('converted2usd+IQR'!E7, 'converted2usd+IQR'!$O7, 'converted2usd+IQR'!$P7) -> 99318.186 | F7: =MEDIAN('converted2usd+IQR'!F7, 'converted2usd+IQR'!$O7, 'converted2usd+IQR'!$P7) -> 86268.191 | G7: =MEDIAN('converted2usd+IQR'!G7, 'converted2usd+IQR'!$O7, 'converted2usd+IQR'!$P7) -> 89479.126 | H7: =MEDIAN('converted2usd+IQR'!H7, 'converted2usd+IQR'!$O7, 'converted2usd+IQR'!$P7) -> 81489.822 | I7: =MEDIAN('converted2usd+IQR'!I7, 'converted2usd+IQR'!$O7, 'converted2usd+IQR'!$P7) -> 163234.05 | ... K7: =MEDIAN('converted2usd+IQR'!K7, 'converted2usd+IQR'!$O7, 'converted2usd+IQR'!$P7) -> 71563.311
A8: Total Income & Expenses | B8: =MEDIAN('converted2usd+IQR'!B8, 'converted2usd+IQR'!$O8, 'converted2usd+IQR'!$P8) -> 36117.711 | C8: =MEDIAN('converted2usd+IQR'!C8, 'converted2usd+IQR'!$O8, 'converted2usd+IQR'!$P8) -> -20675.063 | D8: =MEDIAN('converted2usd+IQR'!D8, 'converted2usd+IQR'!$O8, 'converted2usd+IQR'!$P8) -> -1989.1677 | E8: =MEDIAN('converted2usd+IQR'!E8, 'converted2usd+IQR'!$O8, 'converted2usd+IQR'!$P8) -> -525.03449 | F8: =MEDIAN('converted2usd+IQR'!F8, 'converted2usd+IQR'!$O8, 'converted2usd+IQR'!$P8) -> 2608.6133 | G8: =MEDIAN('converted2usd+IQR'!G8, 'converted2usd+IQR'!$O8, 'converted2usd+IQR'!$P8) -> -19485.826 | H8: =MEDIAN('converted2usd+IQR'!H8, 'converted2usd+IQR'!$O8, 'converted2usd+IQR'!$P8) -> -1203.3321 | I8: =MEDIAN('converted2usd+IQR'!I8, 'converted2usd+IQR'!$O8, 'converted2usd+IQR'!$P8) -> 8981.1225 | ... K8: =MEDIAN('converted2usd+IQR'!K8, 'converted2usd+IQR'!$O8, 'converted2usd+IQR'!$P8) -> 31851.185
A9: Total Assets | B9: =MEDIAN('converted2usd+IQR'!B9, 'converted2usd+IQR'!$O9, 'converted2usd+IQR'!$P9) -> 381927.54 | C9: =MEDIAN('converted2usd+IQR'!C9, 'converted2usd+IQR'!$O9, 'converted2usd+IQR'!$P9) -> 374628.91 | D9: =MEDIAN('converted2usd+IQR'!D9, 'converted2usd+IQR'!$O9, 'converted2usd+IQR'!$P9) -> 392546.43 | E9: =MEDIAN('converted2usd+IQR'!E9, 'converted2usd+IQR'!$O9, 'converted2usd+IQR'!$P9) -> 356706.08 | F9: =MEDIAN('converted2usd+IQR'!F9, 'converted2usd+IQR'!$O9, 'converted2usd+IQR'!$P9) -> 425017.54 | G9: =MEDIAN('converted2usd+IQR'!G9, 'converted2usd+IQR'!$O9, 'converted2usd+IQR'!$P9) -> 383097.35 | H9: =MEDIAN('converted2usd+IQR'!H9, 'converted2usd+IQR'!$O9, 'converted2usd+IQR'!$P9) -> 268130.85 | I9: =MEDIAN('converted2usd+IQR'!I9, 'converted2usd+IQR'!$O9, 'converted2usd+IQR'!$P9) -> 654326.66 | ... K9: =MEDIAN('converted2usd+IQR'!K9, 'converted2usd+IQR'!$O9, 'converted2usd+IQR'!$P9) -> 880860.51
A10: Total Liabs & Net Worth | B10: =MEDIAN('converted2usd+IQR'!B10, 'converted2usd+IQR'!$O10, 'converted2usd+IQR'!$P10) -> 379827.82 | C10: =MEDIAN('converted2usd+IQR'!C10, 'converted2usd+IQR'!$O10, 'converted2usd+IQR'!$P10) -> 374628.91 | D10: =MEDIAN('converted2usd+IQR'!D10, 'converted2usd+IQR'!$O10, 'converted2usd+IQR'!$P10) -> 392546.44 | E10: =MEDIAN('converted2usd+IQR'!E10, 'converted2usd+IQR'!$O10, 'converted2usd+IQR'!$P10) -> 356706.08 | F10: =MEDIAN('converted2usd+IQR'!F10, 'converted2usd+IQR'!$O10, 'converted2usd+IQR'!$P10) -> 425017.54 | G10: =MEDIAN('converted2usd+IQR'!G10, 'converted2usd+IQR'!$O10, 'converted2usd+IQR'!$P10) -> 383097.35 | H10: =MEDIAN('converted2usd+IQR'!H10, 'converted2usd+IQR'!$O10, 'converted2usd+IQR'!$P10) -> 268130.85 | I10: =MEDIAN('converted2usd+IQR'!I10, 'converted2usd+IQR'!$O10, 'converted2usd+IQR'!$P10) -> 654326.66 | ... K10: =MEDIAN('converted2usd+IQR'!K10, 'converted2usd+IQR'!$O10, 'converted2usd+IQR'!$P10) -> 880860.51
A11: Land | B11: =MEDIAN('converted2usd+IQR'!B11, 'converted2usd+IQR'!$O11, 'converted2usd+IQR'!$P11) -> 4810.2632 | C11: =MEDIAN('converted2usd+IQR'!C11, 'converted2usd+IQR'!$O11, 'converted2usd+IQR'!$P11) -> 4022.0578 | D11: =MEDIAN('converted2usd+IQR'!D11, 'converted2usd+IQR'!$O11, 'converted2usd+IQR'!$P11) -> 6082.4113 | E11: =MEDIAN('converted2usd+IQR'!E11, 'converted2usd+IQR'!$O11, 'converted2usd+IQR'!$P11) -> 6230.6034 | F11: =MEDIAN('converted2usd+IQR'!F11, 'converted2usd+IQR'!$O11, 'converted2usd+IQR'!$P11) -> 17790.25 | G11: =MEDIAN('converted2usd+IQR'!G11, 'converted2usd+IQR'!$O11, 'converted2usd+IQR'!$P11) -> 13117.244 | H11: =MEDIAN('converted2usd+IQR'!H11, 'converted2usd+IQR'!$O11, 'converted2usd+IQR'!$P11) -> 7315.5727 | I11: =MEDIAN('converted2usd+IQR'!I11, 'converted2usd+IQR'!$O11, 'converted2usd+IQR'!$P11) -> 6453.7354 | ... K11: =MEDIAN('converted2usd+IQR'!K11, 'converted2usd+IQR'!$O11, 'converted2usd+IQR'!$P11) -> 12851.248
A12: Buildings | B12: =MEDIAN('converted2usd+IQR'!B12, 'converted2usd+IQR'!$O12, 'converted2usd+IQR'!$P12) -> 285805.63 | C12: =MEDIAN('converted2usd+IQR'!C12, 'converted2usd+IQR'!$O12, 'converted2usd+IQR'!$P12) -> 299048.97 | D12: =MEDIAN('converted2usd+IQR'!D12, 'converted2usd+IQR'!$O12, 'converted2usd+IQR'!$P12) -> 327697.8 | E12: =MEDIAN('converted2usd+IQR'!E12, 'converted2usd+IQR'!$O12, 'converted2usd+IQR'!$P12) -> 304895.62 | F12: =MEDIAN('converted2usd+IQR'!F12, 'converted2usd+IQR'!$O12, 'converted2usd+IQR'!$P12) -> 309085.66 | G12: =MEDIAN('converted2usd+IQR'!G12, 'converted2usd+IQR'!$O12, 'converted2usd+IQR'!$P12) -> 269166.68 | H12: =MEDIAN('converted2usd+IQR'!H12, 'converted2usd+IQR'!$O12, 'converted2usd+IQR'!$P12) -> 189077.71 | I12: =MEDIAN('converted2usd+IQR'!I12, 'converted2usd+IQR'!$O12, 'converted2usd+IQR'!$P12) -> 385983.76 | ... K12: =MEDIAN('converted2usd+IQR'!K12, 'converted2usd+IQR'!$O12, 'converted2usd+IQR'!$P12) -> 486355.39
A13: Leasehold Improvements | B13: =MEDIAN('converted2usd+IQR'!B13, 'converted2usd+IQR'!$O13, 'converted2usd+IQR'!$P13) -> 481.1128 | C13: =MEDIAN('converted2usd+IQR'!C13, 'converted2usd+IQR'!$O13, 'converted2usd+IQR'!$P13) -> 409.01884 | D13: =MEDIAN('converted2usd+IQR'!D13, 'converted2usd+IQR'!$O13, 'converted2usd+IQR'!$P13) -> 530.54253 | E13: =MEDIAN('converted2usd+IQR'!E13, 'converted2usd+IQR'!$O13, 'converted2usd+IQR'!$P13) -> 512.96504 | F13: =MEDIAN('converted2usd+IQR'!F13, 'converted2usd+IQR'!$O13, 'converted2usd+IQR'!$P13) -> 590.65779 | G13: =MEDIAN('converted2usd+IQR'!G13, 'converted2usd+IQR'!$O13, 'converted2usd+IQR'!$P13) -> 447.25564 | H13: =MEDIAN('converted2usd+IQR'!H13, 'converted2usd+IQR'!$O13, 'converted2usd+IQR'!$P13) -> 259.55037 | I13: =MEDIAN('converted2usd+IQR'!I13, 'converted2usd+IQR'!$O13, 'converted2usd+IQR'!$P13) -> 1069.1242 | ... K13: =MEDIAN('converted2usd+IQR'!K13, 'converted2usd+IQR'!$O13, 'converted2usd+IQR'!$P13) -> 822.52423
A14: Plant & Equipment | B14: =MEDIAN('converted2usd+IQR'!B14, 'converted2usd+IQR'!$O14, 'converted2usd+IQR'!$P14) -> 7177.9176 | C14: =MEDIAN('converted2usd+IQR'!C14, 'converted2usd+IQR'!$O14, 'converted2usd+IQR'!$P14) -> 7260.9834 | D14: =MEDIAN('converted2usd+IQR'!D14, 'converted2usd+IQR'!$O14, 'converted2usd+IQR'!$P14) -> 7710.2906 | E14: =MEDIAN('converted2usd+IQR'!E14, 'converted2usd+IQR'!$O14, 'converted2usd+IQR'!$P14) -> 6540.977 | F14: =MEDIAN('converted2usd+IQR'!F14, 'converted2usd+IQR'!$O14, 'converted2usd+IQR'!$P14) -> 6282.6927 | G14: =MEDIAN('converted2usd+IQR'!G14, 'converted2usd+IQR'!$O14, 'converted2usd+IQR'!$P14) -> 5355.8385 | H14: =MEDIAN('converted2usd+IQR'!H14, 'converted2usd+IQR'!$O14, 'converted2usd+IQR'!$P14) -> 3636.4045 | I14: =MEDIAN('converted2usd+IQR'!I14, 'converted2usd+IQR'!$O14, 'converted2usd+IQR'!$P14) -> 11539.079 | ... K14: =MEDIAN('converted2usd+IQR'!K14, 'converted2usd+IQR'!$O14, 'converted2usd+IQR'!$P14) -> 12386.308
... A225: Minority Interests | B225: =MEDIAN('converted2usd+IQR'!B225, 'converted2usd+IQR'!$O225, 'converted2usd+IQR'!$P225) -> 0 | C225: =MEDIAN('converted2usd+IQR'!C225, 'converted2usd+IQR'!$O225, 'converted2usd+IQR'!$P225) -> 0 | D225: =MEDIAN('converted2usd+IQR'!D225, 'converted2usd+IQR'!$O225, 'converted2usd+IQR'!$P225) -> 0 | E225: =MEDIAN('converted2usd+IQR'!E225, 'converted2usd+IQR'!$O225, 'converted2usd+IQR'!$P225) -> 0 | F225: =MEDIAN('converted2usd+IQR'!F225, 'converted2usd+IQR'!$O225, 'converted2usd+IQR'!$P225) -> 0 | G225: =MEDIAN('converted2usd+IQR'!G225, 'converted2usd+IQR'!$O225, 'converted2usd+IQR'!$P225) -> 0 | H225: =MEDIAN('converted2usd+IQR'!H225, 'converted2usd+IQR'!$O225, 'converted2usd+IQR'!$P225) -> 0 | I225: =MEDIAN('converted2usd+IQR'!I225, 'converted2usd+IQR'!$O225, 'converted2usd+IQR'!$P225) -> 0 | ... K225: =MEDIAN('converted2usd+IQR'!K225, 'converted2usd+IQR'!$O225, 'converted2usd+IQR'!$P225) -> 0

Sheet final_results
B1: 2015 | C1: 2016 | D1: 2017 | E1: 2018 | F1: 2019 | G1: 2020 | H1: 2021 | I1: 2022 | J1: 2023 | K1: 2024
A2: Periods | B2: 12 | C2: 12 | D2: 12 | E2: 12 | F2: 12 | G2: 12 | H2: 12 | I2: 12 | J2: 12 | K2: 12
A3: Total Non-Current Assets | B3: =+IQR_results_usd!B3*FXs!$C$2 -> 948303.32 | C3: =+IQR_results_usd!C3*FXs!$C$3 -> 1132571.1 | D3: =+IQR_results_usd!D3*FXs!$C$4 -> 1321849.3 | E3: =+IQR_results_usd!E3*FXs!$C$5 -> 1666215.1 | F3: =+IQR_results_usd!F3*FXs!$C$6 -> 2243152.9 | G3: =+IQR_results_usd!G3*FXs!$C$7 -> 2519903.1 | H3: =+IQR_results_usd!H3*FXs!$C$8 -> 3184128 | I3: =+IQR_results_usd!I3*FXs!$C$9 -> 10090610 | J3: =+IQR_results_usd!J3*FXs!$C$10 -> 17149861 | K3: =+IQR_results_usd!K3*FXs!$C$11 -> 24234704
A4: Total Current Assets | B4: =+IQR_results_usd!B4*FXs!$C$2 -> 165868.98 | C4: =+IQR_results_usd!C4*FXs!$C$3 -> 174481.95 | D4: =+IQR_results_usd!D4*FXs!$C$4 -> 188553.52 | E4: =+IQR_results_usd!E4*FXs!$C$5 -> 226511.52 | F4: =+IQR_results_usd!F4*FXs!$C$6 -> 237941.1 | G4: =+IQR_results_usd!G4*FXs!$C$7 -> 438016.49 | H4: =+IQR_results_usd!H4*FXs!$C$8 -> 443279.05 | I4: =+IQR_results_usd!I4*FXs!$C$9 -> 2104055.3 | J4: =+IQR_results_usd!J4*FXs!$C$10 -> 3104576.1 | K4: =+IQR_results_usd!K4*FXs!$C$11 -> 6510695 | M4: bu sheet'teki veriler modelde kullanılacak
A5: Total Equity & Reserves | B5: =+IQR_results_usd!B5*FXs!$C$2 -> -18816.879 | C5: =+IQR_results_usd!C5*FXs!$C$3 -> -6374.964 | D5: =+IQR_results_usd!D5*FXs!$C$4 -> -11517.088 | E5: =+IQR_results_usd!E5*FXs!$C$5 -> -13802.036 | F5: =+IQR_results_usd!F5*FXs!$C$6 -> 41655.046 | G5: =+IQR_results_usd!G5*FXs!$C$7 -> 16267.905 | H5: =+IQR_results_usd!H5*FXs!$C$8 -> 12877.404 | I5: =+IQR_results_usd!I5*FXs!$C$9 -> 5810755.9 | J5: =+IQR_results_usd!J5*FXs!$C$10 -> 10803127 | K5: =+IQR_results_usd!K5*FXs!$C$11 -> 17097795 | M5: Genel tabloda toplam 2240 hücrenin 73 tanesi değişmiş; bunun 68’i üst sınır, 3’ü alt sınır kırpması.
A6: Total Non-Current Liabilities | B6: =+IQR_results_usd!B6*FXs!$C$2 -> 949085.87 | C6: =+IQR_results_usd!C6*FXs!$C$3 -> 1047559.2 | D6: =+IQR_results_usd!D6*FXs!$C$4 -> 1145402.9 | E6: =+IQR_results_usd!E6*FXs!$C$5 -> 1379534.1 | F6: =+IQR_results_usd!F6*FXs!$C$6 -> 1935837.4 | G6: =+IQR_results_usd!G6*FXs!$C$7 -> 2250777.5 | H6: =+IQR_results_usd!H6*FXs!$C$8 -> 2512094.9 | I6: =+IQR_results_usd!I6*FXs!$C$9 -> 3259756.4 | J6: =+IQR_results_usd!J6*FXs!$C$10 -> 5322307.3 | K6: =+IQR_results_usd!K6*FXs!$C$11 -> 11149770
A7: Total Current Liabilities | B7: =+IQR_results_usd!B7*FXs!$C$2 -> 177777.95 | C7: =+IQR_results_usd!C7*FXs!$C$3 -> 265868.83 | D7: =+IQR_results_usd!D7*FXs!$C$4 -> 376517.02 | E7: =+IQR_results_usd!E7*FXs!$C$5 -> 526994.59 | F7: =+IQR_results_usd!F7*FXs!$C$6 -> 503601.55 | G7: =+IQR_results_usd!G7*FXs!$C$7 -> 690874.17 | H7: =+IQR_results_usd!H7*FXs!$C$8 -> 1102434.7 | I7: =+IQR_results_usd!I7*FXs!$C$9 -> 3042187.7 | J7: =+IQR_results_usd!J7*FXs!$C$10 -> 4129002.5 | K7: =+IQR_results_usd!K7*FXs!$C$11 -> 2497833.1
A8: Total Income & Expenses | B8: =+IQR_results_usd!B8*FXs!$C$2 -> 105363.84 | C8: =+IQR_results_usd!C8*FXs!$C$3 -> -72133.792 | D8: =+IQR_results_usd!D8*FXs!$C$4 -> -7653.73 | E8: =+IQR_results_usd!E8*FXs!$C$5 -> -2785.898 | F8: =+IQR_results_usd!F8*FXs!$C$6 -> 15228.112 | G8: =+IQR_results_usd!G8*FXs!$C$7 -> -150451.34 | H8: =+IQR_results_usd!H8*FXs!$C$8 -> -16279.273 | I8: =+IQR_results_usd!I8*FXs!$C$9 -> 167380.9 | J8: =+IQR_results_usd!J8*FXs!$C$10 -> -65447.218 | K8: =+IQR_results_usd!K8*FXs!$C$11 -> 1111728.1
A9: Total Assets | B9: =+IQR_results_usd!B9*FXs!$C$2 -> 1114172.3 | C9: =+IQR_results_usd!C9*FXs!$C$3 -> 1307053 | D9: =+IQR_results_usd!D9*FXs!$C$4 -> 1510402.8 | E9: =+IQR_results_usd!E9*FXs!$C$5 -> 1892726.6 | F9: =+IQR_results_usd!F9*FXs!$C$6 -> 2481094 | G9: =+IQR_results_usd!G9*FXs!$C$7 -> 2957919.6 | H9: =+IQR_results_usd!H9*FXs!$C$8 -> 3627407 | I9: =+IQR_results_usd!I9*FXs!$C$9 -> 12194665 | J9: =+IQR_results_usd!J9*FXs!$C$10 -> 20254437 | K9: =+IQR_results_usd!K9*FXs!$C$11 -> 30745399
A10: Total Liabs & Net Worth | B10: =+IQR_results_usd!B10*FXs!$C$2 -> 1108046.9 | C10: =+IQR_results_usd!C10*FXs!$C$3 -> 1307053 | D10: =+IQR_results_usd!D10*FXs!$C$4 -> 1510402.8 | E10: =+IQR_results_usd!E10*FXs!$C$5 -> 1892726.6 | F10: =+IQR_results_usd!F10*FXs!$C$6 -> 2481094 | G10: =+IQR_results_usd!G10*FXs!$C$7 -> 2957919.6 | H10: =+IQR_results_usd!H10*FXs!$C$8 -> 3627407 | I10: =+IQR_results_usd!I10*FXs!$C$9 -> 12194665 | J10: =+IQR_results_usd!J10*FXs!$C$10 -> 20254437 | K10: =+IQR_results_usd!K10*FXs!$C$11 -> 30745399
A11: Land | B11: =+IQR_results_usd!B11*FXs!$C$2 -> 14032.667 | C11: =+IQR_results_usd!C11*FXs!$C$3 -> 14032.667 | D11: =+IQR_results_usd!D11*FXs!$C$4 -> 23403.323 | E11: =+IQR_results_usd!E11*FXs!$C$5 -> 33060.353 | F11: =+IQR_results_usd!F11*FXs!$C$6 -> 103852.85 | G11: =+IQR_results_usd!G11*FXs!$C$7 -> 101279.09 | H11: =+IQR_results_usd!H11*FXs!$C$8 -> 98968.693 | I11: =+IQR_results_usd!I11*FXs!$C$9 -> 120278.06 | J11: =+IQR_results_usd!J11*FXs!$C$10 -> 290929.45 | K11: =+IQR_results_usd!K11*FXs!$C$11 -> 448557.67
A12: Buildings | B12: =+IQR_results_usd!B12*FXs!$C$2 -> 833762.12 | C12: =+IQR_results_usd!C12*FXs!$C$3 -> 1043360.1 | D12: =+IQR_results_usd!D12*FXs!$C$4 -> 1260884.4 | E12: =+IQR_results_usd!E12*FXs!$C$5 -> 1617813.9 | F12: =+IQR_results_usd!F12*FXs!$C$6 -> 1804326.9 | G12: =+IQR_results_usd!G12*FXs!$C$7 -> 2078253.5 | H12: =+IQR_results_usd!H12*FXs!$C$8 -> 2557937 | I12: =+IQR_results_usd!I12*FXs!$C$9 -> 7193567.1 | J12: =+IQR_results_usd!J12*FXs!$C$10 -> 13525188 | K12: =+IQR_results_usd!K12*FXs!$C$11 -> 16975662
A13: Leasehold Improvements | B13: =+IQR_results_usd!B13*FXs!$C$2 -> 1403.519 | C13: =+IQR_results_usd!C13*FXs!$C$3 -> 1427.037 | D13: =+IQR_results_usd!D13*FXs!$C$4 -> 2041.371 | E13: =+IQR_results_usd!E13*FXs!$C$5 -> 2721.856 | F13: =+IQR_results_usd!F13*FXs!$C$6 -> 3448.04 | G13: =+IQR_results_usd!G13*FXs!$C$7 -> 3453.29 | H13: =+IQR_results_usd!H13*FXs!$C$8 -> 3511.326 | I13: =+IQR_results_usd!I13*FXs!$C$9 -> 19925.234 | J13: =+IQR_results_usd!J13*FXs!$C$10 -> 25704.472 | K13: =+IQR_results_usd!K13*FXs!$C$11 -> 28709.24
A14: Plant & Equipment | B14: =+IQR_results_usd!B14*FXs!$C$2 -> 20939.671 | C14: =+IQR_results_usd!C14*FXs!$C$3 -> 25333.043 | D14: =+IQR_results_usd!D14*FXs!$C$4 -> 29666.922 | E14: =+IQR_results_usd!E14*FXs!$C$5 -> 34707.234 | F14: =+IQR_results_usd!F14*FXs!$C$6 -> 36676.018 | G14: =+IQR_results_usd!G14*FXs!$C$7 -> 41352.778 | H14: =+IQR_results_usd!H14*FXs!$C$8 -> 49195.082 | I14: =+IQR_results_usd!I14*FXs!$C$9 -> 215053.46 | J14: =+IQR_results_usd!J14*FXs!$C$10 -> 368293.23 | K14: =+IQR_results_usd!K14*FXs!$C$11 -> 432329.51
A15: Furniture & Fixtures | B15: =+IQR_results_usd!B15*FXs!$C$2 -> 119819.36 | C15: =+IQR_results_usd!C15*FXs!$C$3 -> 153420.68 | D15: =+IQR_results_usd!D15*FXs!$C$4 -> 181671.88 | E15: =+IQR_results_usd!E15*FXs!$C$5 -> 206840.7 | F15: =+IQR_results_usd!F15*FXs!$C$6 -> 240029.24 | G15: =+IQR_results_usd!G15*FXs!$C$7 -> 259654.77 | H15: =+IQR_results_usd!H15*FXs!$C$8 -> 304228.85 | I15: =+IQR_results_usd!I15*FXs!$C$9 -> 1555545.8 | J15: =+IQR_results_usd!J15*FXs!$C$10 -> 2211598.6 | K15: =+IQR_results_usd!K15*FXs!$C$11 -> 2915529
A16: Vehicles & Transport Equipment | B16: =+IQR_results_usd!B16*FXs!$C$2 -> 78074.387 | C16: =+IQR_results_usd!C16*FXs!$C$3 -> 78665.806 | D16: =+IQR_results_usd!D16*FXs!$C$4 -> 111033.76 | E16: =+IQR_results_usd!E16*FXs!$C$5 -> 140028.73 | F16: =+IQR_results_usd!F16*FXs!$C$6 -> 158375.26 | G16: =+IQR_results_usd!G16*FXs!$C$7 -> 194663.89 | H16: =+IQR_results_usd!H16*FXs!$C$8 -> 224867.58 | I16: =+IQR_results_usd!I16*FXs!$C$9 -> 696144.92 | J16: =+IQR_results_usd!J16*FXs!$C$10 -> 1084077 | K16: =+IQR_results_usd!K16*FXs!$C$11 -> 952913.3
A17: Other Fixed Assets | B17: =+IQR_results_usd!B17*FXs!$C$2 -> 0 | C17: =+IQR_results_usd!C17*FXs!$C$3 -> 0 | D17: =+IQR_results_usd!D17*FXs!$C$4 -> 0 | E17: =+IQR_results_usd!E17*FXs!$C$5 -> 0 | F17: =+IQR_results_usd!F17*FXs!$C$6 -> 0 | G17: =+IQR_results_usd!G17*FXs!$C$7 -> 0 | H17: =+IQR_results_usd!H17*FXs!$C$8 -> 0 | I17: =+IQR_results_usd!I17*FXs!$C$9 -> 14708.053 | J17: =+IQR_results_usd!J17*FXs!$C$10 -> 35116.507 | K17: =+IQR_results_usd!K17*FXs!$C$11 -> 82636.929
... A225: Minority Interests | B225: =+IQR_results_usd!B225*FXs!$C$2 -> 0 | C225: =+IQR_results_usd!C225*FXs!$C$3 -> 0 | D225: =+IQR_results_usd!D225*FXs!$C$4 -> 0 | E225: =+IQR_results_usd!E225*FXs!$C$5 -> 0 | F225: =+IQR_results_usd!F225*FXs!$C$6 -> 0 | G225: =+IQR_results_usd!G225*FXs!$C$7 -> 0 | H225: =+IQR_results_usd!H225*FXs!$C$8 -> 0 | I225: =+IQR_results_usd!I225*FXs!$C$9 -> 0 | J225: =+IQR_results_usd!J225*FXs!$C$10 -> 0 | K225: =+IQR_results_usd!K225*FXs!$C$11 -> 0

Sheet Sayfa1
B1: 2015 | C1: 2016 | D1: 2017 | E1: 2018 | F1: 2019 | G1: 2020 | H1: 2021 | I1: 2022 | J1: 2023 | K1: 2024 | T1: 0
A2: Periods | B2: 12 | C2: 12 | D2: 12 | E2: 12 | F2: 12 | G2: 12 | H2: 12 | I2: 12 | J2: 12 | K2: 12
A3: Total Non-Current Assets | B3: =+(final_results!B3-Raw_Financials!B3)/Raw_Financials!B3 -> 0 | C3: =+(final_results!C3-Raw_Financials!C3)/Raw_Financials!C3 -> 0 | D3: =+(final_results!D3-Raw_Financials!D3)/Raw_Financials!D3 -> 0 | E3: =+(final_results!E3-Raw_Financials!E3)/Raw_Financials!E3 -> 0 | F3: =+(final_results!F3-Raw_Financials!F3)/Raw_Financials!F3 -> 0 | G3: =+(final_results!G3-Raw_Financials!G3)/Raw_Financials!G3 -> 0 | H3: =+(final_results!H3-Raw_Financials!H3)/Raw_Financials!H3 -> 0 | I3: =+(final_results!I3-Raw_Financials!I3)/Raw_Financials!I3 -> 0 | ... K3: =+(final_results!K3-Raw_Financials!K3)/Raw_Financials!K3 -> 0 | M3: =223*10 -> 2230 | N3: adet veri var
A4: Total Current Assets | B4: =+(final_results!B4-Raw_Financials!B4)/Raw_Financials!B4 -> 0 | C4: =+(final_results!C4-Raw_Financials!C4)/Raw_Financials!C4 -> 0 | D4: =+(final_results!D4-Raw_Financials!D4)/Raw_Financials!D4 -> 0 | E4: =+(final_results!E4-Raw_Financials!E4)/Raw_Financials!E4 -> 0 | F4: =+(final_results!F4-Raw_Financials!F4)/Raw_Financials!F4 -> 0 | G4: =+(final_results!G4-Raw_Financials!G4)/Raw_Financials!G4 -> 0 | H4: =+(final_results!H4-Raw_Financials!H4)/Raw_Financials!H4 -> 0 | I4: =+(final_results!I4-Raw_Financials!I4)/Raw_Financials!I4 -> 0 | ... K4: =+(final_results!K4-Raw_Financials!K4)/Raw_Financials!K4 -> 0 | M4: =COUNTIF(B3:K225, ">"&T1) + COUNTIF(B3:K225, "<"&T1) -> 159 | N4: outlier sayısı (adet)
A5: Total Equity & Reserves | B5: =+(final_results!B5-Raw_Financials!B5)/Raw_Financials!B5 -> 0 | C5: =+(final_results!C5-Raw_Financials!C5)/Raw_Financials!C5 -> 0 | D5: =+(final_results!D5-Raw_Financials!D5)/Raw_Financials!D5 -> 0 | E5: =+(final_results!E5-Raw_Financials!E5)/Raw_Financials!E5 -> 0 | F5: =+(final_results!F5-Raw_Financials!F5)/Raw_Financials!F5 -> 0 | G5: =+(final_results!G5-Raw_Financials!G5)/Raw_Financials!G5 -> 0 | H5: =+(final_results!H5-Raw_Financials!H5)/Raw_Financials!H5 -> 0 | I5: =+(final_results!I5-Raw_Financials!I5)/Raw_Financials!I5 -> 0 | ... K5: =+(final_results!K5-Raw_Financials!K5)/Raw_Financials!K5 -> 0 | M5: =+M4/M3 -> 0.071300448 | N5: outlier (%) (adet)
A6: Total Non-Current Liabilities | B6: =+(final_results!B6-Raw_Financials!B6)/Raw_Financials!B6 -> 0 | C6: =+(final_results!C6-Raw_Financials!C6)/Raw_Financials!C6 -> 0 | D6: =+(final_results!D6-Raw_Financials!D6)/Raw_Financials!D6 -> 0 | E6: =+(final_results!E6-Raw_Financials!E6)/Raw_Financials!E6 -> 0 | F6: =+(final_results!F6-Raw_Financials!F6)/Raw_Financials!F6 -> 0 | G6: =+(final_results!G6-Raw_Financials!G6)/Raw_Financials!G6 -> 0 | H6: =+(final_results!H6-Raw_Financials!H6)/Raw_Financials!H6 -> 0 | I6: =+(final_results!I6-Raw_Financials!I6)/Raw_Financials!I6 -> 0 | ... K6: =+(final_results!K6-Raw_Financials!K6)/Raw_Financials!K6 -> 0
A7: Total Current Liabilities | B7: =+(final_results!B7-Raw_Financials!B7)/Raw_Financials!B7 -> 0 | C7: =+(final_results!C7-Raw_Financials!C7)/Raw_Financials!C7 -> 0 | D7: =+(final_results!D7-Raw_Financials!D7)/Raw_Financials!D7 -> 0 | E7: =+(final_results!E7-Raw_Financials!E7)/Raw_Financials!E7 -> 0 | F7: =+(final_results!F7-Raw_Financials!F7)/Raw_Financials!F7 -> 0 | G7: =+(final_results!G7-Raw_Financials!G7)/Raw_Financials!G7 -> 0 | H7: =+(final_results!H7-Raw_Financials!H7)/Raw_Financials!H7 -> 0 | I7: =+(final_results!I7-Raw_Financials!I7)/Raw_Financials!I7 -> -0.026235986 | ... K7: =+(final_results!K7-Raw_Financials!K7)/Raw_Financials!K7 -> 0
A8: Total Income & Expenses | B8: =+(final_results!B8-Raw_Financials!B8)/Raw_Financials!B8 -> -0.62937422 | C8: =+(final_results!C8-Raw_Financials!C8)/Raw_Financials!C8 -> 0 | D8: =+(final_results!D8-Raw_Financials!D8)/Raw_Financials!D8 -> 0 | E8: =+(final_results!E8-Raw_Financials!E8)/Raw_Financials!E8 -> 0 | F8: =+(final_results!F8-Raw_Financials!F8)/Raw_Financials!F8 -> 1.1944944e-16 | G8: =+(final_results!G8-Raw_Financials!G8)/Raw_Financials!G8 -> 0 | H8: =+(final_results!H8-Raw_Financials!H8)/Raw_Financials!H8 -> 0 | I8: =+(final_results!I8-Raw_Financials!I8)/Raw_Financials!I8 -> 0 | ... K8: =+(final_results!K8-Raw_Financials!K8)/Raw_Financials!K8 -> 0
A9: Total Assets | B9: =+(final_results!B9-Raw_Financials!B9)/Raw_Financials!B9 -> 0 | C9: =+(final_results!C9-Raw_Financials!C9)/Raw_Financials!C9 -> 0 | D9: =+(final_results!D9-Raw_Financials!D9)/Raw_Financials!D9 -> 0 | E9: =+(final_results!E9-Raw_Financials!E9)/Raw_Financials!E9 -> 0 | F9: =+(final_results!F9-Raw_Financials!F9)/Raw_Financials!F9 -> 0 | G9: =+(final_results!G9-Raw_Financials!G9)/Raw_Financials!G9 -> 0 | H9: =+(final_results!H9-Raw_Financials!H9)/Raw_Financials!H9 -> -1.2837305e-16 | I9: =+(final_results!I9-Raw_Financials!I9)/Raw_Financials!I9 -> 1.5274262e-16 | ... K9: =+(final_results!K9-Raw_Financials!K9)/Raw_Financials!K9 -> 0
A10: Total Liabs & Net Worth | B10: =+(final_results!B10-Raw_Financials!B10)/Raw_Financials!B10 -> 0 | C10: =+(final_results!C10-Raw_Financials!C10)/Raw_Financials!C10 -> 0 | D10: =+(final_results!D10-Raw_Financials!D10)/Raw_Financials!D10 -> 0 | E10: =+(final_results!E10-Raw_Financials!E10)/Raw_Financials!E10 -> -1.2301335e-16 | F10: =+(final_results!F10-Raw_Financials!F10)/Raw_Financials!F10 -> 0 | G10: =+(final_results!G10-Raw_Financials!G10)/Raw_Financials!G10 -> 0 | H10: =+(final_results!H10-Raw_Financials!H10)/Raw_Financials!H10 -> 1.2837305e-16 | I10: =+(final_results!I10-Raw_Financials!I10)/Raw_Financials!I10 -> 0 | ... K10: =+(final_results!K10-Raw_Financials!K10)/Raw_Financials!K10 -> 0
A11: Land | B11: =+(final_results!B11-Raw_Financials!B11)/Raw_Financials!B11 -> 0 | C11: =+(final_results!C11-Raw_Financials!C11)/Raw_Financials!C11 -> 0 | D11: =+(final_results!D11-Raw_Financials!D11)/Raw_Financials!D11 -> 0 | E11: =+(final_results!E11-Raw_Financials!E11)/Raw_Financials!E11 -> 0 | F11: =+(final_results!F11-Raw_Financials!F11)/Raw_Financials!F11 -> -1.4012052e-16 | G11: =+(final_results!G11-Raw_Financials!G11)/Raw_Financials!G11 -> 0 | H11: =+(final_results!H11-Raw_Financials!H11)/Raw_Financials!H11 -> 0 | I11: =+(final_results!I11-Raw_Financials!I11)/Raw_Financials!I11 -> 1.2098561e-16 | ... K11: =+(final_results!K11-Raw_Financials!K11)/Raw_Financials!K11 -> 0
A12: Buildings | B12: =+(final_results!B12-Raw_Financials!B12)/Raw_Financials!B12 -> 0 | C12: =+(final_results!C12-Raw_Financials!C12)/Raw_Financials!C12 -> 0 | D12: =+(final_results!D12-Raw_Financials!D12)/Raw_Financials!D12 -> 0 | E12: =+(final_results!E12-Raw_Financials!E12)/Raw_Financials!E12 -> 0 | F12: =+(final_results!F12-Raw_Financials!F12)/Raw_Financials!F12 -> 0 | G12: =+(final_results!G12-Raw_Financials!G12)/Raw_Financials!G12 -> -1.1203188e-16 | H12: =+(final_results!H12-Raw_Financials!H12)/Raw_Financials!H12 -> 0 | I12: =+(final_results!I12-Raw_Financials!I12)/Raw_Financials!I12 -> 0 | ... K12: =+(final_results!K12-Raw_Financials!K12)/Raw_Financials!K12 -> 0
A13: Leasehold Improvements | B13: =+(final_results!B13-Raw_Financials!B13)/Raw_Financials!B13 -> 0 | C13: =+(final_results!C13-Raw_Financials!C13)/Raw_Financials!C13 -> 0 | D13: =+(final_results!D13-Raw_Financials!D13)/Raw_Financials!D13 -> 0 | E13: =+(final_results!E13-Raw_Financials!E13)/Raw_Financials!E13 -> 0 | F13: =+(final_results!F13-Raw_Financials!F13)/Raw_Financials!F13 -> 0 | G13: =+(final_results!G13-Raw_Financials!G13)/Raw_Financials!G13 -> 0 | H13: =+(final_results!H13-Raw_Financials!H13)/Raw_Financials!H13 -> -1.2950872e-16 | I13: =+(final_results!I13-Raw_Financials!I13)/Raw_Financials!I13 -> 0 | ... K13: =+(final_results!K13-Raw_Financials!K13)/Raw_Financials!K13 -> 0
A14: Plant & Equipment | B14: =+(final_results!B14-Raw_Financials!B14)/Raw_Financials!B14 -> 0 | C14: =+(final_results!C14-Raw_Financials!C14)/Raw_Financials!C14 -> 0 | D14: =+(final_results!D14-Raw_Financials!D14)/Raw_Financials!D14 -> 0 | E14: =+(final_results!E14-Raw_Financials!E14)/Raw_Financials!E14 -> 0 | F14: =+(final_results!F14-Raw_Financials!F14)/Raw_Financials!F14 -> 0 | G14: =+(final_results!G14-Raw_Financials!G14)/Raw_Financials!G14 -> 0 | H14: =+(final_results!H14-Raw_Financials!H14)/Raw_Financials!H14 -> 0 | I14: =+(final_results!I14-Raw_Financials!I14)/Raw_Financials!I14 -> 0 | ... K14: =+(final_results!K14-Raw_Financials!K14)/Raw_Financials!K14 -> 0
A15: Furniture & Fixtures | B15: =+(final_results!B15-Raw_Financials!B15)/Raw_Financials!B15 -> -1.2144878e-16 | C15: =+(final_results!C15-Raw_Financials!C15)/Raw_Financials!C15 -> 0 | D15: =+(final_results!D15-Raw_Financials!D15)/Raw_Financials!D15 -> 0 | E15: =+(final_results!E15-Raw_Financials!E15)/Raw_Financials!E15 -> 0 | F15: =+(final_results!F15-Raw_Financials!F15)/Raw_Financials!F15 -> 0 | G15: =+(final_results!G15-Raw_Financials!G15)/Raw_Financials!G15 -> -1.1208664e-16 | H15: =+(final_results!H15-Raw_Financials!H15)/Raw_Financials!H15 -> 0 | I15: =+(final_results!I15-Raw_Financials!I15)/Raw_Financials!I15 -> 0 | ... K15: =+(final_results!K15-Raw_Financials!K15)/Raw_Financials!K15 -> 0
A16: Vehicles & Transport Equipment | B16: =+(final_results!B16-Raw_Financials!B16)/Raw_Financials!B16 -> 0 | C16: =+(final_results!C16-Raw_Financials!C16)/Raw_Financials!C16 -> 0 | D16: =+(final_results!D16-Raw_Financials!D16)/Raw_Financials!D16 -> 0 | E16: =+(final_results!E16-Raw_Financials!E16)/Raw_Financials!E16 -> 0 | F16: =+(final_results!F16-Raw_Financials!F16)/Raw_Financials!F16 -> 0 | G16: =+(final_results!G16-Raw_Financials!G16)/Raw_Financials!G16 -> 0 | H16: =+(final_results!H16-Raw_Financials!H16)/Raw_Financials!H16 -> 0.077926942 | I16: =+(final_results!I16-Raw_Financials!I16)/Raw_Financials!I16 -> -0.23155553 | ... K16: =+(final_results!K16-Raw_Financials!K16)/Raw_Financials!K16 -> 0
A17: Other Fixed Assets | B17: =+(final_results!B17-Raw_Financials!B17)/Raw_Financials!B17 -> #DIV/0! | C17: =+(final_results!C17-Raw_Financials!C17)/Raw_Financials!C17 -> #DIV/0! | D17: =+(final_results!D17-Raw_Financials!D17)/Raw_Financials!D17 -> #DIV/0! | E17: =+(final_results!E17-Raw_Financials!E17)/Raw_Financials!E17 -> #DIV/0! | F17: =+(final_results!F17-Raw_Financials!F17)/Raw_Financials!F17 -> #DIV/0! | G17: =+(final_results!G17-Raw_Financials!G17)/Raw_Financials!G17 -> #DIV/0! | H17: =+(final_results!H17-Raw_Financials!H17)/Raw_Financials!H17 -> #DIV/0! | I17: =+(final_results!I17-Raw_Financials!I17)/Raw_Financials!I17 -> 0 | ... K17: =+(final_results!K17-Raw_Financials!K17)/Raw_Financials!K17 -> -0.47336393
... A225: Minority Interests | B225: =+(final_results!B225-Raw_Financials!B225)/Raw_Financials!B225 -> #DIV/0! | C225: =+(final_results!C225-Raw_Financials!C225)/Raw_Financials!C225 -> #DIV/0! | D225: =+(final_results!D225-Raw_Financials!D225)/Raw_Financials!D225 -> #DIV/0! | E225: =+(final_results!E225-Raw_Financials!E225)/Raw_Financials!E225 -> #DIV/0! | F225: =+(final_results!F225-Raw_Financials!F225)/Raw_Financials!F225 -> #DIV/0! | G225: =+(final_results!G225-Raw_Financials!G225)/Raw_Financials!G225 -> #DIV/0! | H225: =+(final_results!H225-Raw_Financials!H225)/Raw_Financials!H225 -> #DIV/0! | I225: =+(final_results!I225-Raw_Financials!I225)/Raw_Financials!I225 -> #DIV/0! | ... K225: =+(final_results!K225-Raw_Financials!K225)/Raw_Financials!K225 -> #DIV/0!

Sheet Sayfa2
B1: 2015 | C1: 2016 | D1: 2017 | E1: 2018 | F1: 2019 | G1: 2020 | H1: 2021 | I1: 2022 | J1: 2023 | K1: 2024
A2: Periods | B2: 12 | C2: 12 | D2: 12 | E2: 12 | F2: 12 | G2: 12 | H2: 12 | I2: 12 | J2: 12 | K2: 12
A3: Total Non-Current Assets | B3: =+final_results!B3-Raw_Financials!B3 -> 0 | C3: =+final_results!C3-Raw_Financials!C3 -> 0 | D3: =+final_results!D3-Raw_Financials!D3 -> 0 | E3: =+final_results!E3-Raw_Financials!E3 -> 0 | F3: =+final_results!F3-Raw_Financials!F3 -> 0 | G3: =+final_results!G3-Raw_Financials!G3 -> 0 | H3: =+final_results!H3-Raw_Financials!H3 -> 0 | I3: =+final_results!I3-Raw_Financials!I3 -> 0 | ... K3: =+final_results!K3-Raw_Financials!K3 -> 0 | M3: =+SUM(Raw_Financials!B3:K225) -> 8.0116304e+08 | N3: tüm verilerin toplamı
A4: Total Current Assets | B4: =+final_results!B4-Raw_Financials!B4 -> 0 | C4: =+final_results!C4-Raw_Financials!C4 -> 0 | D4: =+final_results!D4-Raw_Financials!D4 -> 0 | E4: =+final_results!E4-Raw_Financials!E4 -> 0 | F4: =+final_results!F4-Raw_Financials!F4 -> 0 | G4: =+final_results!G4-Raw_Financials!G4 -> 0 | H4: =+final_results!H4-Raw_Financials!H4 -> 0 | I4: =+final_results!I4-Raw_Financials!I4 -> 0 | ... K4: =+final_results!K4-Raw_Financials!K4 -> 0 | M4: =+SUM(B3:K225) -> -30544087 | N4: outlier olan tutarların toplamı
A5: Total Equity & Reserves | B5: =+final_results!B5-Raw_Financials!B5 -> 0 | C5: =+final_results!C5-Raw_Financials!C5 -> 0 | D5: =+final_results!D5-Raw_Financials!D5 -> 0 | E5: =+final_results!E5-Raw_Financials!E5 -> 0 | F5: =+final_results!F5-Raw_Financials!F5 -> 0 | G5: =+final_results!G5-Raw_Financials!G5 -> 0 | H5: =+final_results!H5-Raw_Financials!H5 -> 0 | I5: =+final_results!I5-Raw_Financials!I5 -> 0 | ... K5: =+final_results!K5-Raw_Financials!K5 -> 0 | M5: =ABS(M4)/M3 -> 0.038124684 | N5: Parasal Oran
A6: Total Non-Current Liabilities | B6: =+final_results!B6-Raw_Financials!B6 -> 0 | C6: =+final_results!C6-Raw_Financials!C6 -> 0 | D6: =+final_results!D6-Raw_Financials!D6 -> 0 | E6: =+final_results!E6-Raw_Financials!E6 -> 0 | F6: =+final_results!F6-Raw_Financials!F6 -> 0 | G6: =+final_results!G6-Raw_Financials!G6 -> 0 | H6: =+final_results!H6-Raw_Financials!H6 -> 0 | I6: =+final_results!I6-Raw_Financials!I6 -> 0 | ... K6: =+final_results!K6-Raw_Financials!K6 -> 0
A7: Total Current Liabilities | B7: =+final_results!B7-Raw_Financials!B7 -> 0 | C7: =+final_results!C7-Raw_Financials!C7 -> 0 | D7: =+final_results!D7-Raw_Financials!D7 -> 0 | E7: =+final_results!E7-Raw_Financials!E7 -> 0 | F7: =+final_results!F7-Raw_Financials!F7 -> 0 | G7: =+final_results!G7-Raw_Financials!G7 -> 0 | H7: =+final_results!H7-Raw_Financials!H7 -> 0 | I7: =+final_results!I7-Raw_Financials!I7 -> -81965.233 | ... K7: =+final_results!K7-Raw_Financials!K7 -> 0
A8: Total Income & Expenses | B8: =+final_results!B8-Raw_Financials!B8 -> -178922.48 | C8: =+final_results!C8-Raw_Financials!C8 -> 0 | D8: =+final_results!D8-Raw_Financials!D8 -> 0 | E8: =+final_results!E8-Raw_Financials!E8 -> 0 | F8: =+final_results!F8-Raw_Financials!F8 -> 0 | G8: =+final_results!G8-Raw_Financials!G8 -> 0 | H8: =+final_results!H8-Raw_Financials!H8 -> 0 | I8: =+final_results!I8-Raw_Financials!I8 -> 0 | ... K8: =+final_results!K8-Raw_Financials!K8 -> 0
A9: Total Assets | B9: =+final_results!B9-Raw_Financials!B9 -> 0 | C9: =+final_results!C9-Raw_Financials!C9 -> 0 | D9: =+final_results!D9-Raw_Financials!D9 -> 0 | E9: =+final_results!E9-Raw_Financials!E9 -> 0 | F9: =+final_results!F9-Raw_Financials!F9 -> 0 | G9: =+final_results!G9-Raw_Financials!G9 -> 0 | H9: =+final_results!H9-Raw_Financials!H9 -> 0 | I9: =+final_results!I9-Raw_Financials!I9 -> 0 | ... K9: =+final_results!K9-Raw_Financials!K9 -> 0 | M9: "Analiz sonucunda verinin %7.1'i (adet bazında) aykırı bulunmuş, ancak bu aykırı değerlerin toplam parasal hacme etkisi (Materiality) sadece %3.8 ile sınırlı kalmıştır. Bu da uygulanan Winsorization yönteminin finansal tablonun ana gövdesini bozmadan, sadece uçlardaki gürültüyü temizlediğini göstermektedir."
A10: Total Liabs & Net Worth | B10: =+final_results!B10-Raw_Financials!B10 -> 0 | C10: =+final_results!C10-Raw_Financials!C10 -> 0 | D10: =+final_results!D10-Raw_Financials!D10 -> 0 | E10: =+final_results!E10-Raw_Financials!E10 -> 0 | F10: =+final_results!F10-Raw_Financials!F10 -> 0 | G10: =+final_results!G10-Raw_Financials!G10 -> 0 | H10: =+final_results!H10-Raw_Financials!H10 -> 0 | I10: =+final_results!I10-Raw_Financials!I10 -> 0 | ... K10: =+final_results!K10-Raw_Financials!K10 -> 0
A11: Land | B11: =+final_results!B11-Raw_Financials!B11 -> 0 | C11: =+final_results!C11-Raw_Financials!C11 -> 0 | D11: =+final_results!D11-Raw_Financials!D11 -> 0 | E11: =+final_results!E11-Raw_Financials!E11 -> 0 | F11: =+final_results!F11-Raw_Financials!F11 -> 0 | G11: =+final_results!G11-Raw_Financials!G11 -> 0 | H11: =+final_results!H11-Raw_Financials!H11 -> 0 | I11: =+final_results!I11-Raw_Financials!I11 -> 0 | ... K11: =+final_results!K11-Raw_Financials!K11 -> 0
A12: Buildings | B12: =+final_results!B12-Raw_Financials!B12 -> 0 | C12: =+final_results!C12-Raw_Financials!C12 -> 0 | D12: =+final_results!D12-Raw_Financials!D12 -> 0 | E12: =+final_results!E12-Raw_Financials!E12 -> 0 | F12: =+final_results!F12-Raw_Financials!F12 -> 0 | G12: =+final_results!G12-Raw_Financials!G12 -> 0 | H12: =+final_results!H12-Raw_Financials!H12 -> 0 | I12: =+final_results!I12-Raw_Financials!I12 -> 0 | ... K12: =+final_results!K12-Raw_Financials!K12 -> 0
A13: Leasehold Improvements | B13: =+final_results!B13-Raw_Financials!B13 -> 0 | C13: =+final_results!C13-Raw_Financials!C13 -> 0 | D13: =+final_results!D13-Raw_Financials!D13 -> 0 | E13: =+final_results!E13-Raw_Financials!E13 -> 0 | F13: =+final_results!F13-Raw_Financials!F13 -> 0 | G13: =+final_results!G13-Raw_Financials!G13 -> 0 | H13: =+final_results!H13-Raw_Financials!H13 -> 0 | I13: =+final_results!I13-Raw_Financials!I13 -> 0 | ... K13: =+final_results!K13-Raw_Financials!K13 -> 0
A14: Plant & Equipment | B14: =+final_results!B14-Raw_Financials!B14 -> 0 | C14: =+final_results!C14-Raw_Financials!C14 -> 0 | D14: =+final_results!D14-Raw_Financials!D14 -> 0 | E14: =+final_results!E14-Raw_Financials!E14 -> 0 | F14: =+final_results!F14-Raw_Financials!F14 -> 0 | G14: =+final_results!G14-Raw_Financials!G14 -> 0 | H14: =+final_results!H14-Raw_Financials!H14 -> 0 | I14: =+final_results!I14-Raw_Financials!I14 -> 0 | ... K14: =+final_results!K14-Raw_Financials!K14 -> 0
A15: Furniture & Fixtures | B15: =+final_results!B15-Raw_Financials!B15 -> 0 | C15: =+final_results!C15-Raw_Financials!C15 -> 0 | D15: =+final_results!D15-Raw_Financials!D15 -> 0 | E15: =+final_results!E15-Raw_Financials!E15 -> 0 | F15: =+final_results!F15-Raw_Financials!F15 -> 0 | G15: =+final_results!G15-Raw_Financials!G15 -> 0 | H15: =+final_results!H15-Raw_Financials!H15 -> 0 | I15: =+final_results!I15-Raw_Financials!I15 -> 0 | ... K15: =+final_results!K15-Raw_Financials!K15 -> 0
A16: Vehicles & Transport Equipment | B16: =+final_results!B16-Raw_Financials!B16 -> 0 | C16: =+final_results!C16-Raw_Financials!C16 -> 0 | D16: =+final_results!D16-Raw_Financials!D16 -> 0 | E16: =+final_results!E16-Raw_Financials!E16 -> 0 | F16: =+final_results!F16-Raw_Financials!F16 -> 0 | G16: =+final_results!G16-Raw_Financials!G16 -> 0 | H16: =+final_results!H16-Raw_Financials!H16 -> 16256.429 | I16: =+final_results!I16-Raw_Financials!I16 -> -209769.49 | ... K16: =+final_results!K16-Raw_Financials!K16 -> 0
A17: Other Fixed Assets | B17: =+final_results!B17-Raw_Financials!B17 -> 0 | C17: =+final_results!C17-Raw_Financials!C17 -> 0 | D17: =+final_results!D17-Raw_Financials!D17 -> 0 | E17: =+final_results!E17-Raw_Financials!E17 -> 0 | F17: =+final_results!F17-Raw_Financials!F17 -> 0 | G17: =+final_results!G17-Raw_Financials!G17 -> 0 | H17: =+final_results!H17-Raw_Financials!H17 -> 0 | I17: =+final_results!I17-Raw_Financials!I17 -> 0 | ... K17: =+final_results!K17-Raw_Financials!K17 -> -74277.748
